<?xml version="1.0" encoding="utf-8"?>
<robot name="b2z1_description">
  <link name="base_link">
    <inertial>
      <origin xyz="0.000458 0.005261 0.000665" rpy="0 0 0" />
      <mass value="35.606" />
      <inertia ixx="0.27466" ixy="-0.000622" ixz="0.00315" iyy="1.0618" iyz="-0.00139" izz="1.1825" />
    </inertial>
    <visual>
      <origin xyz="0 0 0" rpy="0 0 0" />
      <geometry>
        <mesh filename="../meshes/visual/base_link.dae" />
      </geometry>
      <material name="">
        <color rgba="1 1 1 1" />
      </material>
    </visual>
    <collision>
      <origin xyz="0 0 0" rpy="0 0 0" />
        <geometry>
          <box size="0.5 0.28 0.15" />
        </geometry>
    </collision>
  </link>
  <link name="lidar_link">
    <inertial>
      <origin xyz="4.22E-15 1.05E-14 -3.05E-16" rpy="0 0 0" />
      <mass value="6.55E-08" />
      <inertia ixx="1.64E-15" ixy="0" ixz="-1.09E-47" iyy="1.64E-15" iyz="-1.32E-47" izz="1.64E-15" />
    </inertial>
    <collision>
      <origin xyz="0 0 -0.02" rpy="0 0 0" />
      <geometry>
        <cylinder length="0.16" radius="0.076" />
      </geometry>
    </collision>
  </link>
  <joint name="joint_lidar" type="fixed">
    <origin xyz="0.34218 0 0.17851" rpy="0 0 0" />
    <parent link="base_link" />
    <child link="lidar_link" />
    <axis xyz="0 0 0" />
  </joint>
  <link name="f_dc_link">
    <inertial>
      <origin xyz="-3.47E-18 -1.11E-16 1.11E-16" rpy="0 0 0" />
      <mass value="6.54E-08" />
      <inertia ixx="1.64E-15" ixy="1.87E-32" ixz="-6.15E-32" iyy="1.64E-15" iyz="4.93E-32" izz="1.64E-15" />
    </inertial>
  </link>
  <joint name="joint_f_dc" type="fixed">
    <origin xyz="0.41251 0.024997 0.04765" rpy="-2.3562 0 -1.5708" />
    <parent link="base_link" />
    <child link="f_dc_link" />
    <axis xyz="0 0 0" />
  </joint>
  <link name="r_dc_link">
    <inertial>
      <origin xyz="1.63E-16 1.39E-16 2.78E-17" rpy="0 0 0" />
      <mass value="6.55E-08" />
      <inertia ixx="1.64E-15" ixy="-4.94E-44" ixz="4.36E-43" iyy="1.64E-15" iyz="0" izz="1.64E-15" />
    </inertial>
  </link>
  <joint name="joint_r_dc" type="fixed">
    <origin xyz="-0.4081 -0.025 0.024861" rpy="-2.3557 0 1.5708" />
    <parent link="base_link" />
    <child link="r_dc_link" />
    <axis xyz="0 0 0" />
  </joint>
  <link name="imu_link">
    <inertial>
      <origin xyz="-1.11E-16 -2.81E-16 -1.32E-16" rpy="0 0 0" />
      <mass value="6.54E-08" />
      <inertia ixx="1.64E-15" ixy="0" ixz="-1.09E-47" iyy="1.64E-15" iyz="-1.32E-47" izz="1.64E-15" />
    </inertial>
  </link>
  <joint name="joint_imu" type="fixed">
    <origin xyz="0 -0.02341 0.04927" rpy="0 0 0" />
    <parent link="base_link" />
    <child link="imu_link" />
    <axis xyz="0 0 0" />
  </joint>
  <link name="head_Link">
    <inertial>
      <origin xyz="0.33989 -0.000168 0.12029" rpy="0 0 0" />
      <mass value="3.366" />
      <inertia ixx="0.026455" ixy="3.15E-05" ixz="0.00166" iyy="0.029221" iyz="-3.27E-05" izz="0.010918" />
    </inertial>
    <collision>
      <origin xyz="0.41 0 0.005" rpy="0 0 0" />
      <geometry>
        <box size="0.04 0.12 0.14" />
      </geometry>
    </collision>
  </link>
  <joint name="joint_head" type="fixed">
    <origin xyz="0 0 0" rpy="0 0 0" />
    <parent link="base_link" />
    <child link="head_Link" />
    <axis xyz="0 0 0" />
  </joint>
  <link name="tail_link">
    <inertial>
      <origin xyz="-0.37448 0.000488 0.006495" rpy="0 0 0" />
      <mass value="0.777" />
      <inertia ixx="0.0028118" ixy="1.95E-05" ixz="-7.87E-06" iyy="0.0047506" iyz="-1.57E-05" izz="0.0029154" />
    </inertial>
    <collision>
      <origin xyz="-0.405 0 0.005" rpy="0 0 0" />
      <geometry>
        <box size="0.025 0.12 0.14" />
      </geometry>
    </collision>
  </link>
  <joint name="joint_tail" type="fixed">
    <origin xyz="0 0 0" rpy="0 0 0" />
    <parent link="base_link" />
    <child link="tail_link" />
    <axis xyz="0 0 0" />
  </joint>
  <link name="FL_hip">
    <inertial>
      <origin xyz="-0.009305 -0.010228 0.000264" rpy="0 0 0" />
      <mass value="2.256" />
      <inertia ixx="0.0026431" ixy="0.00019234" ixz="-6.76E-06" iyy="0.0046728" iyz="-7.16E-06" izz="0.0034208" />
    </inertial>
    <visual>
      <origin xyz="0 0 0" rpy="0 0 0" />
      <geometry>
        <mesh filename="../meshes/visual/FL_hip.dae" />
      </geometry>
      <material name="">
        <color rgba="1 1 1 1" />
      </material>
    </visual>
    <collision>
      <origin xyz="0 0.12 0" rpy="1.5707963267948966 0 0" />
      <geometry>
        <cylinder length="0.05" radius="0.07" />
      </geometry>
    </collision>
  </link>
  <joint name="FL_hip_joint" type="revolute">
    <origin xyz="0.3285 0.072 0" rpy="0 0 0" />
    <parent link="base_link" />
    <child link="FL_hip" />
    <axis xyz="1 0 0" />
    <limit lower="-0.87" upper="0.87" effort="200" velocity="23" />
  </joint>
  <link name="FL_hip_rotor">
    <!-- <visual>
      <origin rpy="0 1.5707963267948966 0" xyz="0 0 0"/>
      <geometry>
        <cylinder length="0.02" radius="0.05"/>
      </geometry>
    </visual> -->
    <collision>
      <origin rpy="0 1.5707963267948966 0" xyz="0 0 0"/>
      <geometry>
        <cylinder length="0.02" radius="0.05"/>
      </geometry>
    </collision>
    <inertial>
      <origin rpy="0 0 0" xyz="0.0 0.0 0.0"/>
      <mass value="0.2734"/>
      <inertia ixx="0.000144463" ixy="0.0" ixz="0.0" iyy="0.000144463" iyz="0.0" izz="0.000263053"/>
    </inertial>
  </link>
  <joint name="FL_hip_rotor_joint" type="fixed">
    <origin rpy="0 0 0" xyz="0.20205 0.072 0"/>
    <parent link="base_link"/>
    <child link="FL_hip_rotor"/>
  </joint>
  <link name="FL_thigh">
    <inertial>
      <origin xyz="-0.004346 -0.035797 -0.044921" rpy="0 0 0" />
      <mass value="3.591" />
      <inertia ixx="0.041718" ixy="0.00055623" ixz="-0.0022768" iyy="0.041071" iyz="0.005796" izz="0.0065677" />
    </inertial>
    <visual>
      <origin xyz="0 0 0" rpy="0 0 0" />
      <geometry>
        <mesh filename="../meshes/visual/FL_thigh.dae" />
      </geometry>
      <material name="">
        <color rgba="1 1 1 1" />
      </material>
    </visual>
    <collision>
      <origin xyz="-0.025 0 -0.16" rpy="0 1.57 0" />
      <geometry>
        <box size="0.32 0.0445 0.054" />
      </geometry>
    </collision>
  </link>
  <joint name="FL_thigh_joint" type="revolute">
    <origin xyz="0 0.11973 0" rpy="0 0 0" />
    <parent link="FL_hip" />
    <child link="FL_thigh" />
    <axis xyz="0 1 0" />
    <limit lower="-0.94" upper="4.69" effort="200" velocity="23" />
  </joint>
  <link name="FL_thigh_rotor">
    <!-- <visual>
      <origin rpy="1.5707963267948966 0 0" xyz="0 0 0"/>
      <geometry>
        <cylinder length="0.02" radius="0.05"/>
      </geometry>
    </visual> -->
    <collision>
      <origin rpy="1.5707963267948966 0 0" xyz="0 0 0"/>
      <geometry>
        <cylinder length="0.02" radius="0.05"/>
      </geometry>
    </collision>
    <inertial>
      <origin rpy="0 0 0" xyz="0.0 0.0 0.0"/>
      <mass value="0.2734"/>
      <inertia ixx="0.000144463" ixy="0.0" ixz="0.0" iyy="0.000144463" iyz="0.0" izz="0.000263053"/>
    </inertial>
  </link>
  <joint name="FL_thigh_rotor_joint" type="fixed">
    <origin rpy="0 0 0" xyz="0 -0.00798 0"/>
    <parent link="FL_hip"/>
    <child link="FL_thigh_rotor"/>
  </joint>
  <link name="FL_calf">
    <inertial>
      <origin xyz="0.012422 0 -0.12499" rpy="0 0 0" />
      <mass value="0.58094" />
      <inertia ixx="0.01143" ixy="0" ixz="0.000643" iyy="0.011534" iyz="0" izz="0.000331" />
    </inertial>
    <visual>
      <origin xyz="0 0 0" rpy="0 0 0" />
      <geometry>
        <mesh filename="../meshes/visual/FL_calf.dae" />
      </geometry>
      <material name="">
        <color rgba="1 1 1 1" />
      </material>
    </visual>
    <collision>
      <origin rpy="0 1.2 0" xyz="-0.002 0 -0.03"/>
      <geometry>
        <box size="0.1 0.0245 0.018"/>
      </geometry>
    </collision>
    <collision>
      <origin rpy="0 1.35 0" xyz="0.022 0 -0.1"/>
      <geometry>
        <box size="0.1 0.0245 0.018"/>
      </geometry>
    </collision>
    <collision>
      <origin rpy="0 1.53 0" xyz="0.036 0 -0.225"/>
      <geometry>
        <box size="0.15 0.0245 0.015"/>
      </geometry>
    </collision>
    <collision>
      <origin rpy="0 2 0" xyz="0.023 0 -0.31"/>
      <geometry>
        <box size="0.05 0.028 0.035"/>
      </geometry>
    </collision>
  </link>
  <joint name="FL_calf_joint" type="revolute">
    <origin xyz="0 -8.6984E-05 -0.35" rpy="0 0 0" />
    <parent link="FL_thigh" />
    <child link="FL_calf" />
    <axis xyz="0 1 0" />
    <limit lower="-2.82" upper="-0.43" effort="320" velocity="14" />
  </joint>
  <link name="FL_calf_rotor">
    <!-- <visual>
      <origin rpy="1.5707963267948966 0 0" xyz="0 0 0"/>
      <geometry>
        <cylinder length="0.02" radius="0.05"/>
      </geometry>
    </visual> -->
    <collision>
      <origin rpy="1.5707963267948966 0 0" xyz="0 0 0"/>
      <geometry>
        <cylinder length="0.02" radius="0.05"/>
      </geometry>
    </collision>
    <inertial>
      <origin rpy="0 0 0" xyz="0.0 0.0 0.0"/>
      <mass value="0.2734"/>
      <inertia ixx="0.000144463" ixy="0.0" ixz="0.0" iyy="0.000144463" iyz="0.0" izz="0.000263053"/>
    </inertial>
  </link>
  <joint name="FL_calf_rotor_joint" type="fixed">
    <origin rpy="0 0 0" xyz="0 -0.05788 0"/>
    <parent link="FL_thigh"/>
    <child link="FL_calf_rotor"/>
  </joint>
  <link name="FL_foot">
    <inertial>
      <origin xyz="-0.006511 0 -0.010144" rpy="0 0 0" />
      <mass value="0.098183" />
      <inertia ixx="3.8E-05" ixy="0" ixz="1.1E-05" iyy="4.1E-05" iyz="0" izz="4.2E-05" />
    </inertial>
    <collision>
      <origin xyz="0 0 0" rpy="1.57 0 0" />
      <geometry>
        <sphere radius="0.032" />
      </geometry>
    </collision>
  </link>
  <joint name="FL_foot_joint" type="fixed">
    <origin xyz="0 0 -0.35" rpy="0 0 0" />
    <parent link="FL_calf" />
    <child link="FL_foot" />
  </joint>
  <link name="FR_hip">
    <inertial>
      <origin xyz="-0.009305 0.010228 0.000264" rpy="0 0 0" />
      <mass value="2.256" />
      <inertia ixx="0.0026431" ixy="-0.00019234" ixz="-6.76E-06" iyy="0.0046728" iyz="7.16E-06" izz="0.0034208" />
    </inertial>
    <visual>
      <origin xyz="0 0 0" rpy="0 0 0" />
      <geometry>
        <mesh filename="../meshes/visual/FR_hip.dae" />
      </geometry>
      <material name="">
        <color rgba="1 1 1 1" />
      </material>
    </visual>
    <collision>
      <origin xyz="0 -0.12 0" rpy="1.5707963267948966 0 0" />
      <geometry>
        <cylinder length="0.05" radius="0.07" />
      </geometry>
    </collision>
  </link>
  <joint name="FR_hip_joint" type="revolute">
    <origin xyz="0.3285 -0.072 0" rpy="0 0 0" />
    <parent link="base_link" />
    <child link="FR_hip" />
    <axis xyz="1 0 0" />
    <limit lower="-0.87" upper="0.87" effort="200" velocity="23" />
  </joint>
  <link name="FR_hip_rotor">
    <!-- <visual>
      <origin rpy="0 1.5707963267948966 0" xyz="0 0 0"/>
      <geometry>
        <cylinder length="0.02" radius="0.05"/>
      </geometry>
    </visual> -->
    <collision>
      <origin rpy="0 1.5707963267948966 0" xyz="0 0 0"/>
      <geometry>
        <cylinder length="0.02" radius="0.05"/>
      </geometry>
    </collision>
    <inertial>
      <origin rpy="0 0 0" xyz="0.0 0.0 0.0"/>
      <mass value="0.2734"/>
      <inertia ixx="0.000144463" ixy="0.0" ixz="0.0" iyy="0.000144463" iyz="0.0" izz="0.000263053"/>
    </inertial>
  </link>
  <joint name="FR_hip_rotor_joint" type="fixed">
    <origin rpy="0 0 0" xyz="0.20205 -0.072 0"/>
    <parent link="base_link"/>
    <child link="FR_hip_rotor"/>
  </joint>
  <link name="FR_thigh">
    <inertial>
      <origin xyz="-0.004346 0.035797 -0.044921" rpy="0 0 0" />
      <mass value="3.591" />
      <inertia ixx="0.041718" ixy="-0.00055623" ixz="-0.0022768" iyy="0.041071" iyz="-0.005796" izz="0.0065677" />
    </inertial>
    <visual>
      <origin xyz="0 0 0" rpy="0 0 0" />
      <geometry>
        <mesh filename="../meshes/visual/FR_thigh.dae" />
      </geometry>
      <material name="">
        <color rgba="1 1 1 1" />
      </material>
    </visual>
    <collision>
      <origin rpy="0 1.57 0" xyz="-0.03 0 -0.2"/>
      <geometry>
        <box size="0.25 0.028 0.04"/>
      </geometry>
    </collision>
  </link>
  <joint name="FR_thigh_joint" type="revolute">
    <origin xyz="0 -0.11973 0" rpy="0 0 0" />
    <parent link="FR_hip" />
    <child link="FR_thigh" />
    <axis xyz="0 1 0" />
    <limit lower="-0.94" upper="4.69" effort="200" velocity="23" />
  </joint>
  <link name="FR_thigh_rotor">
    <!-- <visual>
      <origin rpy="1.5707963267948966 0 0" xyz="0 0 0"/>
      <geometry>
        <cylinder length="0.02" radius="0.05"/>
      </geometry>
    </visual> -->
    <collision>
      <origin rpy="1.5707963267948966 0 0" xyz="0 0 0"/>
      <geometry>
        <cylinder length="0.02" radius="0.05"/>
      </geometry>
    </collision>
    <inertial>
      <origin rpy="0 0 0" xyz="0.0 0.0 0.0"/>
      <mass value="0.2734"/>
      <inertia ixx="0.000144463" ixy="0.0" ixz="0.0" iyy="0.000144463" iyz="0.0" izz="0.000263053"/>
    </inertial>
  </link>
  <joint name="FR_thigh_rotor_joint" type="fixed">
    <origin rpy="0 0 0" xyz="0 0.00798 0"/>
    <parent link="FR_hip"/>
    <child link="FR_thigh_rotor"/>
  </joint>
  <link name="FR_calf">
    <inertial>
      <origin xyz="0.012422 0 -0.12499" rpy="0 0 0" />
      <mass value="0.58094" />
      <inertia ixx="0.01143" ixy="0" ixz="0.000643" iyy="0.011534" iyz="0" izz="0.000331" />
    </inertial>
    <visual>
      <origin xyz="0 0 0" rpy="0 0 0" />
      <geometry>
        <mesh filename="../meshes/visual/FR_calf.dae" />
      </geometry>
      <material name="">
        <color rgba="1 1 1 1" />
      </material>
    </visual>
    <collision>
      <origin rpy="0 1.2 0" xyz="-0.002 0 -0.03"/>
      <geometry>
        <box size="0.1 0.0245 0.018"/>
      </geometry>
    </collision>
    <collision>
      <origin rpy="0 1.35 0" xyz="0.022 0 -0.1"/>
      <geometry>
        <box size="0.1 0.0245 0.018"/>
      </geometry>
    </collision>
    <collision>
      <origin rpy="0 1.53 0" xyz="0.036 0 -0.225"/>
      <geometry>
        <box size="0.15 0.0245 0.015"/>
      </geometry>
    </collision>
    <collision>
      <origin rpy="0 2 0" xyz="0.023 0 -0.31"/>
      <geometry>
        <box size="0.05 0.028 0.035"/>
      </geometry>
    </collision>
  </link>
  <joint name="FR_calf_joint" type="revolute">
    <origin xyz="0 8.6986E-05 -0.35" rpy="0 0 0" />
    <parent link="FR_thigh" />
    <child link="FR_calf" />
    <axis xyz="0 1 0" />
    <limit lower="-2.82" upper="-0.43" effort="320" velocity="14" />
  </joint>
  <link name="FR_calf_rotor">
    <!-- <visual>
      <origin rpy="1.5707963267948966 0 0" xyz="0 0 0"/>
      <geometry>
        <cylinder length="0.02" radius="0.05"/>
      </geometry>
      <material name="green"/>
    </visual> -->
    <collision>
      <origin rpy="1.5707963267948966 0 0" xyz="0 0 0"/>
      <geometry>
        <cylinder length="0.02" radius="0.05"/>
      </geometry>
    </collision>
    <inertial>
      <origin rpy="0 0 0" xyz="0.0 0.0 0.0"/>
      <mass value="0.2734"/>
      <inertia ixx="0.000144463" ixy="0.0" ixz="0.0" iyy="0.000144463" iyz="0.0" izz="0.000263053"/>
    </inertial>
  </link>
  <joint name="FR_calf_rotor_joint" type="fixed">
    <origin rpy="0 0 0" xyz="0 0.05788 0"/>
    <parent link="FR_thigh"/>
    <child link="FR_calf_rotor"/>
  </joint>
  <link name="FR_foot">
    <inertial>
      <origin xyz="-0.006511 0 -0.010144" rpy="0 0 0" />
      <mass value="0.098183" />
      <inertia ixx="3.8E-05" ixy="0" ixz="1.1E-05" iyy="4.1E-05" iyz="0" izz="4.2E-05" />
    </inertial>
    <collision>
      <origin xyz="0 0 0" rpy="1.57 0 0" />
      <geometry>
        <sphere radius="0.032" />
      </geometry>
    </collision>
  </link>
  <joint name="FR_foot_joint" type="fixed">
    <origin xyz="0 0 -0.35" rpy="0 0 0" />
    <parent link="FR_calf" />
    <child link="FR_foot" />
  </joint>
  <link name="RL_hip">
    <inertial>
      <origin xyz="0.009305 -0.010228 0.000264" rpy="0 0 0" />
      <mass value="2.256" />
      <inertia ixx="0.0026431" ixy="-0.00019234" ixz="6.76E-06" iyy="0.0046728" iyz="-7.16E-06" izz="0.0034208" />
    </inertial>
    <visual>
      <origin xyz="0 0 0" rpy="0 0 0" />
      <geometry>
        <mesh filename="../meshes/visual/RL_hip.dae" />
      </geometry>
      <material name="">
        <color rgba="1 1 1 1" />
      </material>
    </visual>
    <collision>
      <origin xyz="0 0.12 0" rpy="1.5707963267948966 0 0" />
      <geometry>
        <cylinder length="0.05" radius="0.07" />
      </geometry>
    </collision>
  </link>
  <joint name="RL_hip_joint" type="revolute">
    <origin xyz="-0.3285 0.072 0" rpy="0 0 0" />
    <parent link="base_link" />
    <child link="RL_hip" />
    <axis xyz="1 0 0" />
    <limit lower="-0.87" upper="0.87" effort="200" velocity="23" />
  </joint>
  <link name="RL_hip_rotor">
    <!-- <visual>
      <origin rpy="0 1.5707963267948966 0" xyz="0 0 0"/>
      <geometry>
        <cylinder length="0.02" radius="0.05"/>
      </geometry>
    </visual> -->
    <collision>
      <origin rpy="0 1.5707963267948966 0" xyz="0 0 0"/>
      <geometry>
        <cylinder length="0.02" radius="0.05"/>
      </geometry>
    </collision>
    <inertial>
      <origin rpy="0 0 0" xyz="0.0 0.0 0.0"/>
      <mass value="0.2734"/>
      <inertia ixx="0.000144463" ixy="0.0" ixz="0.0" iyy="0.000144463" iyz="0.0" izz="0.000263053"/>
    </inertial>
  </link>
  <joint name="RL_hip_rotor_joint" type="fixed">
    <origin rpy="0 0 0" xyz="-0.20205 0.072 0"/>
    <parent link="base_link"/>
    <child link="RL_hip_rotor"/>
  </joint>
  <link name="RL_thigh">
    <inertial>
      <origin xyz="-0.004346 -0.035797 -0.044921" rpy="0 0 0" />
      <mass value="3.591" />
      <inertia ixx="0.041718" ixy="0.00055623" ixz="-0.0022768" iyy="0.041071" iyz="0.005796" izz="0.0065677" />
    </inertial>
    <visual>
      <origin xyz="0 0 0" rpy="0 0 0" />
      <geometry>
        <mesh filename="../meshes/visual/RL_thigh.dae" />
      </geometry>
      <material name="">
        <color rgba="1 1 1 1" />
      </material>
    </visual>
    <collision>
      <origin rpy="0 1.57 0" xyz="-0.03 0 -0.2"/>
      <geometry>
        <box size="0.25 0.028 0.04"/>
      </geometry>
    </collision>
  </link>
  <joint name="RL_thigh_joint" type="revolute">
    <origin xyz="0 0.11973 0" rpy="0 0 0" />
    <parent link="RL_hip" />
    <child link="RL_thigh" />
    <axis xyz="0 1 0" />
    <limit lower="-0.94" upper="4.69" effort="200" velocity="23" />
  </joint>
  <link name="RL_thigh_rotor">
    <!-- <visual>
      <origin rpy="1.5707963267948966 0 0" xyz="0 0 0"/>
      <geometry>
        <cylinder length="0.02" radius="0.05"/>
      </geometry>
    </visual> -->
    <collision>
      <origin rpy="1.5707963267948966 0 0" xyz="0 0 0"/>
      <geometry>
        <cylinder length="0.02" radius="0.05"/>
      </geometry>
    </collision>
    <inertial>
      <origin rpy="0 0 0" xyz="0.0 0.0 0.0"/>
      <mass value="0.2734"/>
      <inertia ixx="0.000144463" ixy="0.0" ixz="0.0" iyy="0.000144463" iyz="0.0" izz="0.000263053"/>
    </inertial>
  </link>
  <joint name="RL_thigh_rotor_joint" type="fixed">
    <origin rpy="0 0 0" xyz="0 -0.00798 0"/>
    <parent link="RL_hip"/>
    <child link="RL_thigh_rotor"/>
  </joint>
  <link name="RL_calf">
    <inertial>
      <origin xyz="0.012422 0 -0.12499" rpy="0 0 0" />
      <mass value="0.58094" />
      <inertia ixx="0.01143" ixy="0" ixz="0.000643" iyy="0.011534" iyz="0" izz="0.000331" />
    </inertial>
    <visual>
      <origin xyz="0 0 0" rpy="0 0 0" />
      <geometry>
        <mesh filename="../meshes/visual/RL_calf.dae" />
      </geometry>
      <material name="">
        <color rgba="1 1 1 1" />
      </material>
    </visual>
    <collision>
      <origin rpy="0 1.2 0" xyz="-0.002 0 -0.03"/>
      <geometry>
        <box size="0.1 0.0245 0.018"/>
      </geometry>
    </collision>
    <collision>
      <origin rpy="0 1.35 0" xyz="0.022 0 -0.1"/>
      <geometry>
        <box size="0.1 0.0245 0.018"/>
      </geometry>
    </collision>
    <collision>
      <origin rpy="0 1.53 0" xyz="0.036 0 -0.225"/>
      <geometry>
        <box size="0.15 0.0245 0.015"/>
      </geometry>
    </collision>
    <collision>
      <origin rpy="0 2 0" xyz="0.023 0 -0.31"/>
      <geometry>
        <box size="0.05 0.028 0.035"/>
      </geometry>
    </collision>
  </link>
  <joint name="RL_calf_joint" type="revolute">
    <origin xyz="0 -8.6984E-05 -0.35" rpy="0 0 0" />
    <parent link="RL_thigh" />
    <child link="RL_calf" />
    <axis xyz="0 1 0" />
    <limit lower="-2.82" upper="-0.43" effort="320" velocity="14" />
  </joint>
  <link name="RL_calf_rotor">
    <!-- <visual>
      <origin rpy="1.5707963267948966 0 0" xyz="0 0 0"/>
      <geometry>
        <cylinder length="0.02" radius="0.05"/>
      </geometry>
    </visual> -->
    <collision>
      <origin rpy="1.5707963267948966 0 0" xyz="0 0 0"/>
      <geometry>
        <cylinder length="0.02" radius="0.05"/>
      </geometry>
    </collision>
    <inertial>
      <origin rpy="0 0 0" xyz="0.0 0.0 0.0"/>
      <mass value="0.2734"/>
      <inertia ixx="0.000144463" ixy="0.0" ixz="0.0" iyy="0.000144463" iyz="0.0" izz="0.000263053"/>
    </inertial>
  </link>
  <joint name="RL_calf_rotor_joint" type="fixed">
    <origin rpy="0 0 0" xyz="0 -0.05788 0"/>
    <parent link="RL_thigh"/>
    <child link="RL_calf_rotor"/>
  </joint>
  <link name="RL_foot">
    <inertial>
      <origin xyz="-0.006511 0 -0.010144" rpy="0 0 0" />
      <mass value="0.098183" />
      <inertia ixx="3.8E-05" ixy="0" ixz="1.1E-05" iyy="4.1E-05" iyz="0" izz="4.2E-05" />
    </inertial>
    <collision>
      <origin xyz="0 0 0" rpy="1.57 0 0" />
      <geometry>
        <sphere radius="0.032" />
      </geometry>
    </collision>
  </link>
  <joint name="RL_foot_joint" type="fixed">
    <origin xyz="0 0 -0.35" rpy="0 0 0" />
    <parent link="RL_calf" />
    <child link="RL_foot" />
  </joint>
  <link name="RR_hip">
    <inertial>
      <origin xyz="0.009305 -0.010228 0.000264" rpy="0 0 0" />
      <mass value="2.256" />
      <inertia ixx="0.0026431" ixy="0.00019234" ixz="6.76E-06" iyy="0.0046728" iyz="7.16E-06" izz="0.0034208" />
    </inertial>
    <visual>
      <origin xyz="0 0 0" rpy="0 0 0" />
      <geometry>
        <mesh filename="../meshes/visual/RR_hip.dae" />
      </geometry>
      <material name="">
        <color rgba="1 1 1 1" />
      </material>
    </visual>
    <collision>
      <origin xyz="0 -0.12 0" rpy="1.5707963267948966 0 0" />
      <geometry>
        <cylinder length="0.05" radius="0.07" />
      </geometry>
    </collision>
  </link>
  <joint name="RR_hip_joint" type="revolute">
    <origin xyz="-0.3285 -0.072 0" rpy="0 0 0" />
    <parent link="base_link" />
    <child link="RR_hip" />
    <axis xyz="1 0 0" />
    <limit lower="-0.87" upper="0.87" effort="200" velocity="23" />
  </joint>
  <link name="RR_hip_rotor">
    <!-- <visual>
      <origin rpy="0 1.5707963267948966 0" xyz="0 0 0"/>
      <geometry>
        <cylinder length="0.02" radius="0.05"/>
      </geometry>
    </visual> -->
    <collision>
      <origin rpy="0 1.5707963267948966 0" xyz="0 0 0"/>
      <geometry>
        <cylinder length="0.02" radius="0.05"/>
      </geometry>
    </collision>
    <inertial>
      <origin rpy="0 0 0" xyz="0.0 0.0 0.0"/>
      <mass value="0.2734"/>
      <inertia ixx="0.000144463" ixy="0.0" ixz="0.0" iyy="0.000144463" iyz="0.0" izz="0.000263053"/>
    </inertial>
  </link>
  <joint name="RR_hip_rotor_joint" type="fixed">
    <origin rpy="0 0 0" xyz="-0.20205 -0.072 0"/>
    <parent link="base_link"/>
    <child link="RR_hip_rotor"/>
  </joint>
  <link name="RR_thigh">
    <inertial>
      <origin xyz="-0.004346 0.035797 -0.044921" rpy="0 0 0" />
      <mass value="3.591" />
      <inertia ixx="0.041718" ixy="-0.00055623" ixz="-0.0022768" iyy="0.041071" iyz="-0.005796" izz="0.0065677" />
    </inertial>
    <visual>
      <origin xyz="0 0 0" rpy="0 0 0" />
      <geometry>
        <mesh filename="../meshes/visual/RR_thigh.dae" />
      </geometry>
      <material name="">
        <color rgba="1 1 1 1" />
      </material>
    </visual>
    <collision>
      <origin rpy="0 1.57 0" xyz="-0.03 0 -0.2"/>
      <geometry>
        <box size="0.25 0.028 0.04"/>
      </geometry>
    </collision>
  </link>
  <joint name="RR_thigh_joint" type="revolute">
    <origin xyz="0 -0.11973 0" rpy="0 0 0" />
    <parent link="RR_hip" />
    <child link="RR_thigh" />
    <axis xyz="0 1 0" />
    <limit lower="-0.94" upper="4.69" effort="200" velocity="23" />
  </joint>
  <link name="RR_thigh_rotor">
    <!-- <visual>
      <origin rpy="1.5707963267948966 0 0" xyz="0 0 0"/>
      <geometry>
        <cylinder length="0.02" radius="0.05"/>
      </geometry>
    </visual> -->
    <collision>
      <origin rpy="1.5707963267948966 0 0" xyz="0 0 0"/>
      <geometry>
        <cylinder length="0.02" radius="0.05"/>
      </geometry>
    </collision>
    <inertial>
      <origin rpy="0 0 0" xyz="0.0 0.0 0.0"/>
      <mass value="0.2734"/>
      <inertia ixx="0.000144463" ixy="0.0" ixz="0.0" iyy="0.000144463" iyz="0.0" izz="0.000263053"/>
    </inertial>
  </link>
  <joint name="RR_thigh_rotor_joint" type="fixed">
    <origin rpy="0 0 0" xyz="0 0.00798 0"/>
    <parent link="RR_hip"/>
    <child link="RR_thigh_rotor"/>
  </joint>
  <link name="RR_calf">
    <inertial>
      <origin xyz="0.012422 0 -0.12499" rpy="0 0 0" />
      <mass value="0.58094" />
      <inertia ixx="0.01143" ixy="0" ixz="0.000643" iyy="0.011534" iyz="0" izz="0.000331" />
    </inertial>
    <visual>
      <origin xyz="0 0 0" rpy="0 0 0" />
      <geometry>
        <mesh filename="../meshes/visual/RR_calf.dae" />
      </geometry>
      <material name="">
        <color rgba="1 1 1 1" />
      </material>
    </visual>
    <collision>
      <origin rpy="0 1.2 0" xyz="-0.002 0 -0.03"/>
      <geometry>
        <box size="0.1 0.0245 0.018"/>
      </geometry>
    </collision>
    <collision>
      <origin rpy="0 1.35 0" xyz="0.022 0 -0.1"/>
      <geometry>
        <box size="0.1 0.0245 0.018"/>
      </geometry>
    </collision>
    <collision>
      <origin rpy="0 1.53 0" xyz="0.036 0 -0.225"/>
      <geometry>
        <box size="0.15 0.0245 0.015"/>
      </geometry>
    </collision>
    <collision>
      <origin rpy="0 2 0" xyz="0.023 0 -0.31"/>
      <geometry>
        <box size="0.05 0.028 0.035"/>
      </geometry>
    </collision>
  </link>
  <joint name="RR_calf_joint" type="revolute">
    <origin xyz="0 8.6986E-05 -0.35" rpy="0 0 0" />
    <parent link="RR_thigh" />
    <child link="RR_calf" />
    <axis xyz="0 1 0" />
    <limit lower="-2.82" upper="-0.43" effort="320" velocity="14" />
  </joint>
  <link name="RR_calf_rotor">
    <!-- <visual>
      <origin rpy="1.5707963267948966 0 0" xyz="0 0 0"/>
      <geometry>
        <cylinder length="0.02" radius="0.05"/>
      </geometry>
    </visual> -->
    <collision>
      <origin rpy="1.5707963267948966 0 0" xyz="0 0 0"/>
      <geometry>
        <cylinder length="0.02" radius="0.05"/>
      </geometry>
    </collision>
    <inertial>
      <origin rpy="0 0 0" xyz="0.0 0.0 0.0"/>
      <mass value="0.2734"/>
      <inertia ixx="0.000144463" ixy="0.0" ixz="0.0" iyy="0.000144463" iyz="0.0" izz="0.000263053"/>
    </inertial>
  </link>
  <joint name="RR_calf_rotor_joint" type="fixed">
    <origin rpy="0 0 0" xyz="0 0.05788 0"/>
    <parent link="RR_thigh"/>
    <child link="RR_calf_rotor"/>
  </joint>
  <link name="RR_foot">
    <inertial>
      <origin xyz="-0.006511 0 -0.010144" rpy="0 0 0" />
      <mass value="0.098183" />
      <inertia ixx="3.8E-05" ixy="0" ixz="1.1E-05" iyy="4.1E-05" iyz="0" izz="4.2E-05" />
    </inertial>
    <collision>
      <origin xyz="0 0 0" rpy="1.57 0 0" />
      <geometry>
        <sphere radius="0.032" />
      </geometry>
    </collision>
  </link>
  <joint name="RR_foot_joint" type="fixed">
    <origin xyz="0 -8.6984E-05 -0.35" rpy="0 0 0" />
    <parent link="RR_calf" />
    <child link="RR_foot" />
  </joint>
  <link name="f_oc_link">
    <inertial>
      <origin xyz="-2.78E-17 1.73E-18 0" rpy="0 0 0" />
      <mass value="6.55E-08" />
      <inertia ixx="1.64E-15" ixy="-1.32E-47" ixz="0" iyy="1.64E-15" iyz="1.09E-47" izz="1.64E-15" />
    </inertial>
  </link>
  <joint name="joint_f_oc" type="fixed">
    <origin xyz="0.39079 0 -0.013433" rpy="-1.5708 0 -1.5708" />
    <parent link="base_link" />
    <child link="f_oc_link" />
    <axis xyz="0 0 0" />
  </joint>
  <link name="r_oc_link">
    <inertial>
      <origin xyz="-1.3E-19 3.47E-18 -5.55E-17" rpy="0 0 0" />
      <mass value="6.55E-08" />
      <inertia ixx="1.64E-15" ixy="1.33E-47" ixz="-6.38E-33" iyy="1.64E-15" iyz="-1.64E-47" izz="1.64E-15" />
    </inertial>
  </link>
  <joint name="joint_r_oc" type="fixed">
    <origin xyz="-0.38451 0 -0.023249" rpy="-1.5708 0 1.5708" />
    <parent link="base_link" />
    <child link="r_oc_link" />
    <axis xyz="0 0 0" />
  </joint>

  <joint name="b2_z1_joint" type="fixed">
    <origin rpy="0 0 0" xyz="0.15 0. 0.10"/>
    <parent link="base_link"/>
    <child link="spacer"/>
  </joint>
  <link name="spacer">
    <inertial>
      <origin xyz="4.22E-15 1.05E-14 -3.05E-16" rpy="0 0 0" />
      <mass value="6.55E-08" />
      <inertia ixx="1.64E-15" ixy="0" ixz="-1.09E-47" iyy="1.64E-15" iyz="-1.32E-47" izz="1.64E-15" />
    </inertial>
    <visual>
      <origin xyz="0.0 0 0.0" rpy="0 0 0" />
      <geometry>
        <box size="0.2 0.2 0.05" />
      </geometry>
      <material name="">
        <color rgba="1 1 1 1" />
      </material>
    </visual>
    <collision>
      <origin xyz="0.0 0 0.0" rpy="0 0 0" />
        <geometry>
          <box size="0.2 0.2 0.05" />
        </geometry>
    </collision>
  </link>
  <joint name="spacer_joint" type="fixed">
    <origin rpy="0 0 0" xyz="0.02 0. 0.025"/>
    <parent link="spacer"/>
    <child link="link00"/>
  </joint>
  <link name="link00">
    <visual>
      <origin rpy="0 0 0" xyz="0 0 0"/>
      <geometry>
        <mesh filename="../meshes/visual/z1_Link00.dae" scale="1 1 1"/>
      </geometry>
    </visual>
    <collision>
      <geometry>
        <cylinder length="0.051" radius="0.0325"/>
      </geometry>
      <origin rpy="0 0 0" xyz="0 0 0.0255"/>
    </collision>
    <inertial>
      <origin rpy="0 0 0" xyz="-0.00334984 -0.00013615 0.02495843"/>
      <mass value="0.47247481"/>
      <inertia ixx="0.00037937" ixy="3.5e-07" ixz="1.037e-05" iyy="0.00041521" iyz="9.9e-07" izz="0.00053066"/>
    </inertial>
  </link>
  <joint name="joint1" type="revolute">
    <origin rpy="0 0 0" xyz="0 0 0.0585"/>
    <parent link="link00"/>
    <child link="link01"/>
    <axis xyz="0 0 1"/>
    <dynamics damping="1.0" friction="1.0"/>
    <limit effort="30.0" lower="-2.6179938779914944" upper="2.6179938779914944" velocity="10"/>
  </joint>
  <link name="link01">
    <visual>
      <origin rpy="0 0 0" xyz="0 0 0"/>
      <geometry>
        <mesh filename="../meshes/visual/z1_Link01.dae" scale="1 1 1"/>
      </geometry>
    </visual>
    <inertial>
      <origin rpy="0 0 0" xyz="2.47e-06 -0.00025198 0.02317169"/>
      <mass value="0.67332551"/>
      <inertia ixx="0.00128328" ixy="6e-08" ixz="4e-07" iyy="0.00071931" iyz="-5e-07" izz="0.00083936"/>
    </inertial>
  </link>
  <joint name="joint2" type="revolute">
    <origin rpy="0 0 0" xyz="0 0 0.045"/>
    <parent link="link01"/>
    <child link="link02"/>
    <axis xyz="0 1 0"/>
    <dynamics damping="2.0" friction="2.0"/>
    <limit effort="60.0" lower="0.0" upper="3.141592653589793" velocity="10"/>
  </joint>
  <link name="link02">
    <visual>
      <origin rpy="0 0 0" xyz="0 0 0"/>
      <geometry>
        <mesh filename="../meshes/visual/z1_Link02.dae" scale="1 1 1"/>
      </geometry>
    </visual>
    <collision>
      <geometry>
        <cylinder length="0.102" radius="0.0325"/>
      </geometry>
      <origin rpy="1.5707963267948966 0 0" xyz="0 0 0"/>
    </collision>
    <collision>
      <geometry>
        <cylinder length="0.235" radius="0.0225"/>
      </geometry>
      <origin rpy="0 1.5707963267948966 0" xyz="-0.16249999999999998 0 0"/>
    </collision>
    <collision>
      <geometry>
        <cylinder length="0.051" radius="0.0325"/>
      </geometry>
      <origin rpy="1.5707963267948966 0 0" xyz="-0.35 0 0"/>
    </collision>
    <inertial>
      <origin rpy="0 0 0" xyz="-0.11012601 0.00240029 0.00158266"/>
      <mass value="1.19132258"/>
      <inertia ixx="0.00102138" ixy="-0.00062358" ixz="-5.13e-06" iyy="0.02429457" iyz="2.1e-06" izz="0.02466114"/>
    </inertial>
  </link>
  <joint name="joint3" type="revolute">
    <origin rpy="0 0 0" xyz="-0.35 0 0"/>
    <parent link="link02"/>
    <child link="link03"/>
    <axis xyz="0 1 0"/>
    <dynamics damping="1.0" friction="1.0"/>
    <limit effort="30.0" lower="-4.782202150464463" upper="0.0" velocity="10"/>
  </joint>
  <link name="link03">
    <visual>
      <origin rpy="0 0 0" xyz="0 0 0"/>
      <geometry>
        <mesh filename="../meshes/visual/z1_Link03.dae" scale="1 1 1"/>
      </geometry>
    </visual>
    <collision>
      <geometry>
        <cylinder length="0.116" radius="0.02"/>
      </geometry>
      <origin rpy="0 1.5707963267948966 0" xyz="0.128 0 0.055"/>
    </collision>
    <collision>
      <geometry>
        <cylinder length="0.059" radius="0.0325"/>
      </geometry>
      <origin rpy="0 1.5707963267948966 0" xyz="0.2205 0 0.055"/>
    </collision>
    <inertial>
      <origin rpy="0 0 0" xyz="0.10609208 -0.00541815 0.03476383"/>
      <mass value="0.83940874"/>
      <inertia ixx="0.00108061" ixy="8.669e-05" ixz="0.00208102" iyy="0.00954238" iyz="1.332e-05" izz="0.00886621"/>
    </inertial>
  </link>
  <joint name="joint4" type="revolute">
    <origin rpy="0 0 0" xyz="0.218 0 0.057"/>
    <parent link="link03"/>
    <child link="link04"/>
    <axis xyz="0 1 0"/>
    <dynamics damping="1.0" friction="1.0"/>
    <limit effort="30.0" lower="-1.7453292519943295" upper="1.5707963267948966" velocity="10"/>
  </joint>
  <link name="link04">
    <visual>
      <origin rpy="0 0 0" xyz="0 0 0"/>
      <geometry>
        <mesh filename="../meshes/visual/z1_Link04.dae" scale="1 1 1"/>
      </geometry>
    </visual>
    <collision>
      <geometry>
        <cylinder length="0.073" radius="0.0325"/>
      </geometry>
      <origin rpy="1.5707963267948966 0 0" xyz="0.0472 0 0"/>
    </collision>
    <inertial>
      <origin rpy="0 0 0" xyz="0.04366681 0.00364738 -0.00170192"/>
      <mass value="0.56404563"/>
      <inertia ixx="0.00031576" ixy="-8.13e-05" ixz="-4.091e-05" iyy="0.00092996" iyz="5.96e-06" izz="0.00097912"/>
    </inertial>
  </link>
  <joint name="joint5" type="revolute">
    <origin rpy="0 0 0" xyz="0.07 0.0 0.0"/>
    <parent link="link04"/>
    <child link="link05"/>
    <axis xyz="0 0 1"/>
    <dynamics damping="1.0" friction="1.0"/>
    <limit effort="30.0" lower="-1.7278759594743864" upper="1.7278759594743864" velocity="10"/>
  </joint>
  <link name="link05">
    <visual>
      <origin rpy="0 0 0" xyz="0 0 0"/>
      <geometry>
        <mesh filename="../meshes/visual/z1_Link05.dae" scale="1 1 1"/>
      </geometry>
    </visual>
    <inertial>
      <origin rpy="0 0 0" xyz="0.03121533 0.0 0.00646316"/>
      <mass value="0.38938492"/>
      <inertia ixx="0.00017605" ixy="-4e-07" ixz="-5.689e-05" iyy="0.00055896" iyz="1.3e-07" izz="0.0005386"/>
    </inertial>
  </link>
  <joint name="joint6" type="revolute">
    <origin rpy="0 0 0" xyz="0.0492 0.0 0.0"/>
    <parent link="link05"/>
    <child link="link06"/>
    <axis xyz="1 0 0"/>
    <dynamics damping="1.0" friction="1.0"/>
    <limit effort="30.0" lower="-2.792526803190927" upper="2.792526803190927" velocity="10"/>
  </joint>
  <link name="link06">
    <visual>
      <origin rpy="0 0 0" xyz="0 0 0"/>
      <geometry>
        <mesh filename="../meshes/visual/z1_Link06.dae" scale="1 1 1"/>
      </geometry>
    </visual>
    <collision>
      <geometry>
        <cylinder length="0.051" radius="0.0325"/>
      </geometry>
      <origin rpy="0 1.5707963267948966 0" xyz="0.0255 0 0"/>
    </collision>
    <inertial>
      <origin rpy="0 0 0" xyz="0.0241569 -0.00017355 -0.00143876"/>
      <mass value="0.28875807"/>
      <inertia ixx="0.00018328" ixy="-1.22e-06" ixz="-5.4e-07" iyy="0.0001475" iyz="-8e-08" izz="0.0001468"/>
    </inertial>
  </link>
  <joint name="gripperStator" type="fixed">
    <origin rpy="0 0 0" xyz="0.051 0.0 0.0"/>
    <parent link="link06"/>
    <child link="gripperStator"/>
  </joint>
  <link name="gripperStator">
    <visual>
      <geometry>
        <mesh filename="../meshes/visual/z1_GripperStator.dae" scale="1 1 1"/>
      </geometry>
    </visual>
    <!-- <collision>
      <geometry>
        <mesh filename="package://b2z1_description/meshes/collision/z1_GripperStator.STL" scale="1 1 1"/>
      </geometry>
    </collision> -->
    <inertial>
      <origin rpy="0 0 0" xyz="0.04764427 -0.00035819 -0.00249162"/>
      <mass value="0.52603655"/>
      <inertia ixx="0.00038683" ixy="3.59e-06" ixz="-7.662e-05" iyy="0.00068614" iyz="-2.09e-06" izz="0.00066293"/>
    </inertial>
  </link>
  <joint name="jointGripper" type="revolute">
    <origin rpy="0 0 0" xyz="0.049 0.0 0"/>
    <parent link="gripperStator"/>
    <child link="gripperMover"/>
    <axis xyz="0 1 0"/>
    <dynamics damping="1.0" friction="1.0"/>
    <limit effort="30.0" lower="-1.5707963267948966" upper="0.0" velocity="10"/>
  </joint>
  <link name="gripperMover">
    <visual>
      <geometry>
        <mesh filename="../meshes/visual/z1_GripperMover.dae" scale="1 1 1"/>
      </geometry>
    </visual>
    <!-- <collision>
      <geometry>
        <mesh filename="package://b2z1_description/meshes/collision/z1_GripperMover.STL" scale="1 1 1"/>
      </geometry>
    </collision> -->
    <inertial>
      <origin rpy="0 0 0" xyz="0.01320633 0.00476708 0.00380534"/>
      <mass value="0.27621302"/>
      <inertia ixx="0.00017716" ixy="-1.683e-05" ixz="1.786e-05" iyy="0.00026787" iyz="-2.62e-06" izz="0.00035728"/>
    </inertial>
  </link>
</robot>
